<?xml version="1.0" ?>
<!-- =================================================================================== -->
<!-- |    This document was autogenerated by xacro from 4x4.xacro                      | -->
<!-- |    EDITING THIS FILE BY HAND IS NOT RECOMMENDED                                 | -->
<!-- =================================================================================== -->
<robot name="4x4">
  <!-- Rviz colors -->
  <material name="black">
    <color rgba="0.0 0.0 0.0 1.0"/>
  </material>
  <material name="blue">
    <color rgba="0.0 0.0 0.8 1.0"/>
  </material>
  <material name="green">
    <color rgba="0.0 0.8 0.0 1.0"/>
  </material>
  <material name="grey">
    <color rgba="0.2 0.2 0.2 1.0"/>
  </material>
  <material name="orange">
    <color rgba="1.0 0.4235294117647059 0.0392156862745098 1.0"/>
  </material>
  <material name="brown">
    <color rgba="0.8705882352941177 0.8117647058823529 0.7647058823529411 1.0"/>
  </material>
  <material name="red">
    <color rgba="0.8 0.0 0.0 1.0"/>
  </material>
  <material name="white">
    <color rgba="1.0 1.0 1.0 1.0"/>
  </material>
  <!-- Used for fixing robot to Gazebo 'base_link' -->
  <link name="world"/>
  <!-- Base Link -->
  <joint name="fixed" type="fixed">
    <parent link="world"/>
    <child link="base_link"/>
  </joint>
  <link name="base_link">
    <visual>
      <geometry>
        <sphere radius="0.001"/>
      </geometry>
      <origin rpy="0 0 0" xyz="0.0 0.0 0.0"/>
    </visual>
    <collision>
      <geometry>
        <sphere radius="0.001"/>
      </geometry>
    </collision>
  </link>
  <joint name="1_4x4_fixed" type="fixed">
    <origin rpy="0.0 0.0 0.0" xyz="0.0 0.0 0.0"/>
    <parent link="base_link"/>
    <child link="1_4x4_base_link"/>
  </joint>
  <link name="1_4x4_base_link">
    <collision>
      <origin rpy="0 0 0" xyz="0 0 0"/>
      <geometry>
        <mesh filename="package://xela_models/mesh/4x4.stl" scale="1 1 1"/>
      </geometry>
    </collision>
    <visual>
      <origin rpy="0 0 0" xyz="0 0 0"/>
      <geometry>
        <mesh filename="package://xela_models/mesh/4x4.stl" scale="1 1 1"/>
      </geometry>
      <material name="red"/>
    </visual>
  </link>
  <link name="1_4x4_1_taxel_base_link">
    <visual>
      <geometry>
        <sphere radius="0.001"/>
      </geometry>
      <origin rpy="0 0 0" xyz="0.0 0.0 0.0"/>
      <material name="blue"/>
    </visual>
    <collision>
      <geometry>
        <sphere radius="0.001"/>
      </geometry>
    </collision>
  </link>
  <link name="1_4x4_1_base2x">
    <visual>
      <geometry>
        <sphere radius="0.0001"/>
      </geometry>
      <origin rpy="0 0 0" xyz="0.0053666 0.018816640000000003 0.004"/>
      <material name="blue"/>
    </visual>
    <collision>
      <geometry>
        <sphere radius="0.0001"/>
      </geometry>
    </collision>
  </link>
  <link name="1_4x4_1_x2y">
    <visual>
      <geometry>
        <sphere radius="0.0001"/>
      </geometry>
      <origin rpy="0 0 0" xyz="0.0 0.0 0.0"/>
      <material name="blue"/>
    </visual>
    <collision>
      <geometry>
        <sphere radius="0.0001"/>
      </geometry>
    </collision>
  </link>
  <joint name="1_4x4_1_joint_x" type="prismatic">
    <origin rpy="0.0 0.0 0.0" xyz="0.0053666 0.018816640000000003 0.004"/>
    <parent link="1_4x4_base_link"/>
    <child link="1_4x4_1_base2x"/>
    <axis xyz="1 0 0"/>
    <limit effort="100.0" lower="-0.0015" upper="0.0015" velocity="0.5"/>
  </joint>
  <joint name="1_4x4_1_joint_y" type="prismatic">
    <origin rpy="0.0 0.0 0.0" xyz="0.0 0.0 0.0"/>
    <parent link="1_4x4_1_base2x"/>
    <child link="1_4x4_1_x2y"/>
    <axis xyz="0 1 0"/>
    <limit effort="100.0" lower="-0.0015" upper="0.0015" velocity="0.5"/>
  </joint>
  <joint name="1_4x4_1_joint_z" type="prismatic">
    <origin rpy="0.0 0.0 0.0" xyz="0.0 0.0 0.0"/>
    <parent link="1_4x4_1_x2y"/>
    <child link="1_4x4_1_taxel_base_link"/>
    <axis xyz="0 0 1"/>
    <limit effort="100.0" lower="-0.001" upper="0.000" velocity="0.5"/>
  </joint>
  <link name="1_4x4_2_taxel_base_link">
    <visual>
      <geometry>
        <sphere radius="0.001"/>
      </geometry>
      <origin rpy="0 0 0" xyz="0.0 0.0 0.0"/>
      <material name="blue"/>
    </visual>
    <collision>
      <geometry>
        <sphere radius="0.001"/>
      </geometry>
    </collision>
  </link>
  <link name="1_4x4_2_base2x">
    <visual>
      <geometry>
        <sphere radius="0.0001"/>
      </geometry>
      <origin rpy="0 0 0" xyz="0.010033199999999999 0.018816640000000003 0.004"/>
      <material name="blue"/>
    </visual>
    <collision>
      <geometry>
        <sphere radius="0.0001"/>
      </geometry>
    </collision>
  </link>
  <link name="1_4x4_2_x2y">
    <visual>
      <geometry>
        <sphere radius="0.0001"/>
      </geometry>
      <origin rpy="0 0 0" xyz="0.0 0.0 0.0"/>
      <material name="blue"/>
    </visual>
    <collision>
      <geometry>
        <sphere radius="0.0001"/>
      </geometry>
    </collision>
  </link>
  <joint name="1_4x4_2_joint_x" type="prismatic">
    <origin rpy="0.0 0.0 0.0" xyz="0.010033199999999999 0.018816640000000003 0.004"/>
    <parent link="1_4x4_base_link"/>
    <child link="1_4x4_2_base2x"/>
    <axis xyz="1 0 0"/>
    <limit effort="100.0" lower="-0.0015" upper="0.0015" velocity="0.5"/>
  </joint>
  <joint name="1_4x4_2_joint_y" type="prismatic">
    <origin rpy="0.0 0.0 0.0" xyz="0.0 0.0 0.0"/>
    <parent link="1_4x4_2_base2x"/>
    <child link="1_4x4_2_x2y"/>
    <axis xyz="0 1 0"/>
    <limit effort="100.0" lower="-0.0015" upper="0.0015" velocity="0.5"/>
  </joint>
  <joint name="1_4x4_2_joint_z" type="prismatic">
    <origin rpy="0.0 0.0 0.0" xyz="0.0 0.0 0.0"/>
    <parent link="1_4x4_2_x2y"/>
    <child link="1_4x4_2_taxel_base_link"/>
    <axis xyz="0 0 1"/>
    <limit effort="100.0" lower="-0.001" upper="0.000" velocity="0.5"/>
  </joint>
  <link name="1_4x4_3_taxel_base_link">
    <visual>
      <geometry>
        <sphere radius="0.001"/>
      </geometry>
      <origin rpy="0 0 0" xyz="0.0 0.0 0.0"/>
      <material name="blue"/>
    </visual>
    <collision>
      <geometry>
        <sphere radius="0.001"/>
      </geometry>
    </collision>
  </link>
  <link name="1_4x4_3_base2x">
    <visual>
      <geometry>
        <sphere radius="0.0001"/>
      </geometry>
      <origin rpy="0 0 0" xyz="0.014699799999999999 0.018816640000000003 0.004"/>
      <material name="blue"/>
    </visual>
    <collision>
      <geometry>
        <sphere radius="0.0001"/>
      </geometry>
    </collision>
  </link>
  <link name="1_4x4_3_x2y">
    <visual>
      <geometry>
        <sphere radius="0.0001"/>
      </geometry>
      <origin rpy="0 0 0" xyz="0.0 0.0 0.0"/>
      <material name="blue"/>
    </visual>
    <collision>
      <geometry>
        <sphere radius="0.0001"/>
      </geometry>
    </collision>
  </link>
  <joint name="1_4x4_3_joint_x" type="prismatic">
    <origin rpy="0.0 0.0 0.0" xyz="0.014699799999999999 0.018816640000000003 0.004"/>
    <parent link="1_4x4_base_link"/>
    <child link="1_4x4_3_base2x"/>
    <axis xyz="1 0 0"/>
    <limit effort="100.0" lower="-0.0015" upper="0.0015" velocity="0.5"/>
  </joint>
  <joint name="1_4x4_3_joint_y" type="prismatic">
    <origin rpy="0.0 0.0 0.0" xyz="0.0 0.0 0.0"/>
    <parent link="1_4x4_3_base2x"/>
    <child link="1_4x4_3_x2y"/>
    <axis xyz="0 1 0"/>
    <limit effort="100.0" lower="-0.0015" upper="0.0015" velocity="0.5"/>
  </joint>
  <joint name="1_4x4_3_joint_z" type="prismatic">
    <origin rpy="0.0 0.0 0.0" xyz="0.0 0.0 0.0"/>
    <parent link="1_4x4_3_x2y"/>
    <child link="1_4x4_3_taxel_base_link"/>
    <axis xyz="0 0 1"/>
    <limit effort="100.0" lower="-0.001" upper="0.000" velocity="0.5"/>
  </joint>
  <link name="1_4x4_4_taxel_base_link">
    <visual>
      <geometry>
        <sphere radius="0.001"/>
      </geometry>
      <origin rpy="0 0 0" xyz="0.0 0.0 0.0"/>
      <material name="blue"/>
    </visual>
    <collision>
      <geometry>
        <sphere radius="0.001"/>
      </geometry>
    </collision>
  </link>
  <link name="1_4x4_4_base2x">
    <visual>
      <geometry>
        <sphere radius="0.0001"/>
      </geometry>
      <origin rpy="0 0 0" xyz="0.0193664 0.018816640000000003 0.004"/>
      <material name="blue"/>
    </visual>
    <collision>
      <geometry>
        <sphere radius="0.0001"/>
      </geometry>
    </collision>
  </link>
  <link name="1_4x4_4_x2y">
    <visual>
      <geometry>
        <sphere radius="0.0001"/>
      </geometry>
      <origin rpy="0 0 0" xyz="0.0 0.0 0.0"/>
      <material name="blue"/>
    </visual>
    <collision>
      <geometry>
        <sphere radius="0.0001"/>
      </geometry>
    </collision>
  </link>
  <joint name="1_4x4_4_joint_x" type="prismatic">
    <origin rpy="0.0 0.0 0.0" xyz="0.0193664 0.018816640000000003 0.004"/>
    <parent link="1_4x4_base_link"/>
    <child link="1_4x4_4_base2x"/>
    <axis xyz="1 0 0"/>
    <limit effort="100.0" lower="-0.0015" upper="0.0015" velocity="0.5"/>
  </joint>
  <joint name="1_4x4_4_joint_y" type="prismatic">
    <origin rpy="0.0 0.0 0.0" xyz="0.0 0.0 0.0"/>
    <parent link="1_4x4_4_base2x"/>
    <child link="1_4x4_4_x2y"/>
    <axis xyz="0 1 0"/>
    <limit effort="100.0" lower="-0.0015" upper="0.0015" velocity="0.5"/>
  </joint>
  <joint name="1_4x4_4_joint_z" type="prismatic">
    <origin rpy="0.0 0.0 0.0" xyz="0.0 0.0 0.0"/>
    <parent link="1_4x4_4_x2y"/>
    <child link="1_4x4_4_taxel_base_link"/>
    <axis xyz="0 0 1"/>
    <limit effort="100.0" lower="-0.001" upper="0.000" velocity="0.5"/>
  </joint>
  <link name="1_4x4_5_taxel_base_link">
    <visual>
      <geometry>
        <sphere radius="0.001"/>
      </geometry>
      <origin rpy="0 0 0" xyz="0.0 0.0 0.0"/>
      <material name="blue"/>
    </visual>
    <collision>
      <geometry>
        <sphere radius="0.001"/>
      </geometry>
    </collision>
  </link>
  <link name="1_4x4_5_base2x">
    <visual>
      <geometry>
        <sphere radius="0.0001"/>
      </geometry>
      <origin rpy="0 0 0" xyz="0.0053666 0.014149980000000003 0.004"/>
      <material name="blue"/>
    </visual>
    <collision>
      <geometry>
        <sphere radius="0.0001"/>
      </geometry>
    </collision>
  </link>
  <link name="1_4x4_5_x2y">
    <visual>
      <geometry>
        <sphere radius="0.0001"/>
      </geometry>
      <origin rpy="0 0 0" xyz="0.0 0.0 0.0"/>
      <material name="blue"/>
    </visual>
    <collision>
      <geometry>
        <sphere radius="0.0001"/>
      </geometry>
    </collision>
  </link>
  <joint name="1_4x4_5_joint_x" type="prismatic">
    <origin rpy="0.0 0.0 0.0" xyz="0.0053666 0.014149980000000003 0.004"/>
    <parent link="1_4x4_base_link"/>
    <child link="1_4x4_5_base2x"/>
    <axis xyz="1 0 0"/>
    <limit effort="100.0" lower="-0.0015" upper="0.0015" velocity="0.5"/>
  </joint>
  <joint name="1_4x4_5_joint_y" type="prismatic">
    <origin rpy="0.0 0.0 0.0" xyz="0.0 0.0 0.0"/>
    <parent link="1_4x4_5_base2x"/>
    <child link="1_4x4_5_x2y"/>
    <axis xyz="0 1 0"/>
    <limit effort="100.0" lower="-0.0015" upper="0.0015" velocity="0.5"/>
  </joint>
  <joint name="1_4x4_5_joint_z" type="prismatic">
    <origin rpy="0.0 0.0 0.0" xyz="0.0 0.0 0.0"/>
    <parent link="1_4x4_5_x2y"/>
    <child link="1_4x4_5_taxel_base_link"/>
    <axis xyz="0 0 1"/>
    <limit effort="100.0" lower="-0.001" upper="0.000" velocity="0.5"/>
  </joint>
  <link name="1_4x4_6_taxel_base_link">
    <visual>
      <geometry>
        <sphere radius="0.001"/>
      </geometry>
      <origin rpy="0 0 0" xyz="0.0 0.0 0.0"/>
      <material name="blue"/>
    </visual>
    <collision>
      <geometry>
        <sphere radius="0.001"/>
      </geometry>
    </collision>
  </link>
  <link name="1_4x4_6_base2x">
    <visual>
      <geometry>
        <sphere radius="0.0001"/>
      </geometry>
      <origin rpy="0 0 0" xyz="0.010033199999999999 0.014149980000000003 0.004"/>
      <material name="blue"/>
    </visual>
    <collision>
      <geometry>
        <sphere radius="0.0001"/>
      </geometry>
    </collision>
  </link>
  <link name="1_4x4_6_x2y">
    <visual>
      <geometry>
        <sphere radius="0.0001"/>
      </geometry>
      <origin rpy="0 0 0" xyz="0.0 0.0 0.0"/>
      <material name="blue"/>
    </visual>
    <collision>
      <geometry>
        <sphere radius="0.0001"/>
      </geometry>
    </collision>
  </link>
  <joint name="1_4x4_6_joint_x" type="prismatic">
    <origin rpy="0.0 0.0 0.0" xyz="0.010033199999999999 0.014149980000000003 0.004"/>
    <parent link="1_4x4_base_link"/>
    <child link="1_4x4_6_base2x"/>
    <axis xyz="1 0 0"/>
    <limit effort="100.0" lower="-0.0015" upper="0.0015" velocity="0.5"/>
  </joint>
  <joint name="1_4x4_6_joint_y" type="prismatic">
    <origin rpy="0.0 0.0 0.0" xyz="0.0 0.0 0.0"/>
    <parent link="1_4x4_6_base2x"/>
    <child link="1_4x4_6_x2y"/>
    <axis xyz="0 1 0"/>
    <limit effort="100.0" lower="-0.0015" upper="0.0015" velocity="0.5"/>
  </joint>
  <joint name="1_4x4_6_joint_z" type="prismatic">
    <origin rpy="0.0 0.0 0.0" xyz="0.0 0.0 0.0"/>
    <parent link="1_4x4_6_x2y"/>
    <child link="1_4x4_6_taxel_base_link"/>
    <axis xyz="0 0 1"/>
    <limit effort="100.0" lower="-0.001" upper="0.000" velocity="0.5"/>
  </joint>
  <link name="1_4x4_7_taxel_base_link">
    <visual>
      <geometry>
        <sphere radius="0.001"/>
      </geometry>
      <origin rpy="0 0 0" xyz="0.0 0.0 0.0"/>
      <material name="blue"/>
    </visual>
    <collision>
      <geometry>
        <sphere radius="0.001"/>
      </geometry>
    </collision>
  </link>
  <link name="1_4x4_7_base2x">
    <visual>
      <geometry>
        <sphere radius="0.0001"/>
      </geometry>
      <origin rpy="0 0 0" xyz="0.014699799999999999 0.014149980000000003 0.004"/>
      <material name="blue"/>
    </visual>
    <collision>
      <geometry>
        <sphere radius="0.0001"/>
      </geometry>
    </collision>
  </link>
  <link name="1_4x4_7_x2y">
    <visual>
      <geometry>
        <sphere radius="0.0001"/>
      </geometry>
      <origin rpy="0 0 0" xyz="0.0 0.0 0.0"/>
      <material name="blue"/>
    </visual>
    <collision>
      <geometry>
        <sphere radius="0.0001"/>
      </geometry>
    </collision>
  </link>
  <joint name="1_4x4_7_joint_x" type="prismatic">
    <origin rpy="0.0 0.0 0.0" xyz="0.014699799999999999 0.014149980000000003 0.004"/>
    <parent link="1_4x4_base_link"/>
    <child link="1_4x4_7_base2x"/>
    <axis xyz="1 0 0"/>
    <limit effort="100.0" lower="-0.0015" upper="0.0015" velocity="0.5"/>
  </joint>
  <joint name="1_4x4_7_joint_y" type="prismatic">
    <origin rpy="0.0 0.0 0.0" xyz="0.0 0.0 0.0"/>
    <parent link="1_4x4_7_base2x"/>
    <child link="1_4x4_7_x2y"/>
    <axis xyz="0 1 0"/>
    <limit effort="100.0" lower="-0.0015" upper="0.0015" velocity="0.5"/>
  </joint>
  <joint name="1_4x4_7_joint_z" type="prismatic">
    <origin rpy="0.0 0.0 0.0" xyz="0.0 0.0 0.0"/>
    <parent link="1_4x4_7_x2y"/>
    <child link="1_4x4_7_taxel_base_link"/>
    <axis xyz="0 0 1"/>
    <limit effort="100.0" lower="-0.001" upper="0.000" velocity="0.5"/>
  </joint>
  <link name="1_4x4_8_taxel_base_link">
    <visual>
      <geometry>
        <sphere radius="0.001"/>
      </geometry>
      <origin rpy="0 0 0" xyz="0.0 0.0 0.0"/>
      <material name="blue"/>
    </visual>
    <collision>
      <geometry>
        <sphere radius="0.001"/>
      </geometry>
    </collision>
  </link>
  <link name="1_4x4_8_base2x">
    <visual>
      <geometry>
        <sphere radius="0.0001"/>
      </geometry>
      <origin rpy="0 0 0" xyz="0.0193664 0.014149980000000003 0.004"/>
      <material name="blue"/>
    </visual>
    <collision>
      <geometry>
        <sphere radius="0.0001"/>
      </geometry>
    </collision>
  </link>
  <link name="1_4x4_8_x2y">
    <visual>
      <geometry>
        <sphere radius="0.0001"/>
      </geometry>
      <origin rpy="0 0 0" xyz="0.0 0.0 0.0"/>
      <material name="blue"/>
    </visual>
    <collision>
      <geometry>
        <sphere radius="0.0001"/>
      </geometry>
    </collision>
  </link>
  <joint name="1_4x4_8_joint_x" type="prismatic">
    <origin rpy="0.0 0.0 0.0" xyz="0.0193664 0.014149980000000003 0.004"/>
    <parent link="1_4x4_base_link"/>
    <child link="1_4x4_8_base2x"/>
    <axis xyz="1 0 0"/>
    <limit effort="100.0" lower="-0.0015" upper="0.0015" velocity="0.5"/>
  </joint>
  <joint name="1_4x4_8_joint_y" type="prismatic">
    <origin rpy="0.0 0.0 0.0" xyz="0.0 0.0 0.0"/>
    <parent link="1_4x4_8_base2x"/>
    <child link="1_4x4_8_x2y"/>
    <axis xyz="0 1 0"/>
    <limit effort="100.0" lower="-0.0015" upper="0.0015" velocity="0.5"/>
  </joint>
  <joint name="1_4x4_8_joint_z" type="prismatic">
    <origin rpy="0.0 0.0 0.0" xyz="0.0 0.0 0.0"/>
    <parent link="1_4x4_8_x2y"/>
    <child link="1_4x4_8_taxel_base_link"/>
    <axis xyz="0 0 1"/>
    <limit effort="100.0" lower="-0.001" upper="0.000" velocity="0.5"/>
  </joint>
  <link name="1_4x4_9_taxel_base_link">
    <visual>
      <geometry>
        <sphere radius="0.001"/>
      </geometry>
      <origin rpy="0 0 0" xyz="0.0 0.0 0.0"/>
      <material name="blue"/>
    </visual>
    <collision>
      <geometry>
        <sphere radius="0.001"/>
      </geometry>
    </collision>
  </link>
  <link name="1_4x4_9_base2x">
    <visual>
      <geometry>
        <sphere radius="0.0001"/>
      </geometry>
      <origin rpy="0 0 0" xyz="0.0053666 0.009483320000000002 0.004"/>
      <material name="blue"/>
    </visual>
    <collision>
      <geometry>
        <sphere radius="0.0001"/>
      </geometry>
    </collision>
  </link>
  <link name="1_4x4_9_x2y">
    <visual>
      <geometry>
        <sphere radius="0.0001"/>
      </geometry>
      <origin rpy="0 0 0" xyz="0.0 0.0 0.0"/>
      <material name="blue"/>
    </visual>
    <collision>
      <geometry>
        <sphere radius="0.0001"/>
      </geometry>
    </collision>
  </link>
  <joint name="1_4x4_9_joint_x" type="prismatic">
    <origin rpy="0.0 0.0 0.0" xyz="0.0053666 0.009483320000000002 0.004"/>
    <parent link="1_4x4_base_link"/>
    <child link="1_4x4_9_base2x"/>
    <axis xyz="1 0 0"/>
    <limit effort="100.0" lower="-0.0015" upper="0.0015" velocity="0.5"/>
  </joint>
  <joint name="1_4x4_9_joint_y" type="prismatic">
    <origin rpy="0.0 0.0 0.0" xyz="0.0 0.0 0.0"/>
    <parent link="1_4x4_9_base2x"/>
    <child link="1_4x4_9_x2y"/>
    <axis xyz="0 1 0"/>
    <limit effort="100.0" lower="-0.0015" upper="0.0015" velocity="0.5"/>
  </joint>
  <joint name="1_4x4_9_joint_z" type="prismatic">
    <origin rpy="0.0 0.0 0.0" xyz="0.0 0.0 0.0"/>
    <parent link="1_4x4_9_x2y"/>
    <child link="1_4x4_9_taxel_base_link"/>
    <axis xyz="0 0 1"/>
    <limit effort="100.0" lower="-0.001" upper="0.000" velocity="0.5"/>
  </joint>
  <link name="1_4x4_10_taxel_base_link">
    <visual>
      <geometry>
        <sphere radius="0.001"/>
      </geometry>
      <origin rpy="0 0 0" xyz="0.0 0.0 0.0"/>
      <material name="blue"/>
    </visual>
    <collision>
      <geometry>
        <sphere radius="0.001"/>
      </geometry>
    </collision>
  </link>
  <link name="1_4x4_10_base2x">
    <visual>
      <geometry>
        <sphere radius="0.0001"/>
      </geometry>
      <origin rpy="0 0 0" xyz="0.010033199999999999 0.009483320000000002 0.004"/>
      <material name="blue"/>
    </visual>
    <collision>
      <geometry>
        <sphere radius="0.0001"/>
      </geometry>
    </collision>
  </link>
  <link name="1_4x4_10_x2y">
    <visual>
      <geometry>
        <sphere radius="0.0001"/>
      </geometry>
      <origin rpy="0 0 0" xyz="0.0 0.0 0.0"/>
      <material name="blue"/>
    </visual>
    <collision>
      <geometry>
        <sphere radius="0.0001"/>
      </geometry>
    </collision>
  </link>
  <joint name="1_4x4_10_joint_x" type="prismatic">
    <origin rpy="0.0 0.0 0.0" xyz="0.010033199999999999 0.009483320000000002 0.004"/>
    <parent link="1_4x4_base_link"/>
    <child link="1_4x4_10_base2x"/>
    <axis xyz="1 0 0"/>
    <limit effort="100.0" lower="-0.0015" upper="0.0015" velocity="0.5"/>
  </joint>
  <joint name="1_4x4_10_joint_y" type="prismatic">
    <origin rpy="0.0 0.0 0.0" xyz="0.0 0.0 0.0"/>
    <parent link="1_4x4_10_base2x"/>
    <child link="1_4x4_10_x2y"/>
    <axis xyz="0 1 0"/>
    <limit effort="100.0" lower="-0.0015" upper="0.0015" velocity="0.5"/>
  </joint>
  <joint name="1_4x4_10_joint_z" type="prismatic">
    <origin rpy="0.0 0.0 0.0" xyz="0.0 0.0 0.0"/>
    <parent link="1_4x4_10_x2y"/>
    <child link="1_4x4_10_taxel_base_link"/>
    <axis xyz="0 0 1"/>
    <limit effort="100.0" lower="-0.001" upper="0.000" velocity="0.5"/>
  </joint>
  <link name="1_4x4_11_taxel_base_link">
    <visual>
      <geometry>
        <sphere radius="0.001"/>
      </geometry>
      <origin rpy="0 0 0" xyz="0.0 0.0 0.0"/>
      <material name="blue"/>
    </visual>
    <collision>
      <geometry>
        <sphere radius="0.001"/>
      </geometry>
    </collision>
  </link>
  <link name="1_4x4_11_base2x">
    <visual>
      <geometry>
        <sphere radius="0.0001"/>
      </geometry>
      <origin rpy="0 0 0" xyz="0.014699799999999999 0.009483320000000002 0.004"/>
      <material name="blue"/>
    </visual>
    <collision>
      <geometry>
        <sphere radius="0.0001"/>
      </geometry>
    </collision>
  </link>
  <link name="1_4x4_11_x2y">
    <visual>
      <geometry>
        <sphere radius="0.0001"/>
      </geometry>
      <origin rpy="0 0 0" xyz="0.0 0.0 0.0"/>
      <material name="blue"/>
    </visual>
    <collision>
      <geometry>
        <sphere radius="0.0001"/>
      </geometry>
    </collision>
  </link>
  <joint name="1_4x4_11_joint_x" type="prismatic">
    <origin rpy="0.0 0.0 0.0" xyz="0.014699799999999999 0.009483320000000002 0.004"/>
    <parent link="1_4x4_base_link"/>
    <child link="1_4x4_11_base2x"/>
    <axis xyz="1 0 0"/>
    <limit effort="100.0" lower="-0.0015" upper="0.0015" velocity="0.5"/>
  </joint>
  <joint name="1_4x4_11_joint_y" type="prismatic">
    <origin rpy="0.0 0.0 0.0" xyz="0.0 0.0 0.0"/>
    <parent link="1_4x4_11_base2x"/>
    <child link="1_4x4_11_x2y"/>
    <axis xyz="0 1 0"/>
    <limit effort="100.0" lower="-0.0015" upper="0.0015" velocity="0.5"/>
  </joint>
  <joint name="1_4x4_11_joint_z" type="prismatic">
    <origin rpy="0.0 0.0 0.0" xyz="0.0 0.0 0.0"/>
    <parent link="1_4x4_11_x2y"/>
    <child link="1_4x4_11_taxel_base_link"/>
    <axis xyz="0 0 1"/>
    <limit effort="100.0" lower="-0.001" upper="0.000" velocity="0.5"/>
  </joint>
  <link name="1_4x4_12_taxel_base_link">
    <visual>
      <geometry>
        <sphere radius="0.001"/>
      </geometry>
      <origin rpy="0 0 0" xyz="0.0 0.0 0.0"/>
      <material name="blue"/>
    </visual>
    <collision>
      <geometry>
        <sphere radius="0.001"/>
      </geometry>
    </collision>
  </link>
  <link name="1_4x4_12_base2x">
    <visual>
      <geometry>
        <sphere radius="0.0001"/>
      </geometry>
      <origin rpy="0 0 0" xyz="0.0193664 0.009483320000000002 0.004"/>
      <material name="blue"/>
    </visual>
    <collision>
      <geometry>
        <sphere radius="0.0001"/>
      </geometry>
    </collision>
  </link>
  <link name="1_4x4_12_x2y">
    <visual>
      <geometry>
        <sphere radius="0.0001"/>
      </geometry>
      <origin rpy="0 0 0" xyz="0.0 0.0 0.0"/>
      <material name="blue"/>
    </visual>
    <collision>
      <geometry>
        <sphere radius="0.0001"/>
      </geometry>
    </collision>
  </link>
  <joint name="1_4x4_12_joint_x" type="prismatic">
    <origin rpy="0.0 0.0 0.0" xyz="0.0193664 0.009483320000000002 0.004"/>
    <parent link="1_4x4_base_link"/>
    <child link="1_4x4_12_base2x"/>
    <axis xyz="1 0 0"/>
    <limit effort="100.0" lower="-0.0015" upper="0.0015" velocity="0.5"/>
  </joint>
  <joint name="1_4x4_12_joint_y" type="prismatic">
    <origin rpy="0.0 0.0 0.0" xyz="0.0 0.0 0.0"/>
    <parent link="1_4x4_12_base2x"/>
    <child link="1_4x4_12_x2y"/>
    <axis xyz="0 1 0"/>
    <limit effort="100.0" lower="-0.0015" upper="0.0015" velocity="0.5"/>
  </joint>
  <joint name="1_4x4_12_joint_z" type="prismatic">
    <origin rpy="0.0 0.0 0.0" xyz="0.0 0.0 0.0"/>
    <parent link="1_4x4_12_x2y"/>
    <child link="1_4x4_12_taxel_base_link"/>
    <axis xyz="0 0 1"/>
    <limit effort="100.0" lower="-0.001" upper="0.000" velocity="0.5"/>
  </joint>
  <link name="1_4x4_13_taxel_base_link">
    <visual>
      <geometry>
        <sphere radius="0.001"/>
      </geometry>
      <origin rpy="0 0 0" xyz="0.0 0.0 0.0"/>
      <material name="blue"/>
    </visual>
    <collision>
      <geometry>
        <sphere radius="0.001"/>
      </geometry>
    </collision>
  </link>
  <link name="1_4x4_13_base2x">
    <visual>
      <geometry>
        <sphere radius="0.0001"/>
      </geometry>
      <origin rpy="0 0 0" xyz="0.0053666 0.00481666 0.004"/>
      <material name="blue"/>
    </visual>
    <collision>
      <geometry>
        <sphere radius="0.0001"/>
      </geometry>
    </collision>
  </link>
  <link name="1_4x4_13_x2y">
    <visual>
      <geometry>
        <sphere radius="0.0001"/>
      </geometry>
      <origin rpy="0 0 0" xyz="0.0 0.0 0.0"/>
      <material name="blue"/>
    </visual>
    <collision>
      <geometry>
        <sphere radius="0.0001"/>
      </geometry>
    </collision>
  </link>
  <joint name="1_4x4_13_joint_x" type="prismatic">
    <origin rpy="0.0 0.0 0.0" xyz="0.0053666 0.00481666 0.004"/>
    <parent link="1_4x4_base_link"/>
    <child link="1_4x4_13_base2x"/>
    <axis xyz="1 0 0"/>
    <limit effort="100.0" lower="-0.0015" upper="0.0015" velocity="0.5"/>
  </joint>
  <joint name="1_4x4_13_joint_y" type="prismatic">
    <origin rpy="0.0 0.0 0.0" xyz="0.0 0.0 0.0"/>
    <parent link="1_4x4_13_base2x"/>
    <child link="1_4x4_13_x2y"/>
    <axis xyz="0 1 0"/>
    <limit effort="100.0" lower="-0.0015" upper="0.0015" velocity="0.5"/>
  </joint>
  <joint name="1_4x4_13_joint_z" type="prismatic">
    <origin rpy="0.0 0.0 0.0" xyz="0.0 0.0 0.0"/>
    <parent link="1_4x4_13_x2y"/>
    <child link="1_4x4_13_taxel_base_link"/>
    <axis xyz="0 0 1"/>
    <limit effort="100.0" lower="-0.001" upper="0.000" velocity="0.5"/>
  </joint>
  <link name="1_4x4_14_taxel_base_link">
    <visual>
      <geometry>
        <sphere radius="0.001"/>
      </geometry>
      <origin rpy="0 0 0" xyz="0.0 0.0 0.0"/>
      <material name="blue"/>
    </visual>
    <collision>
      <geometry>
        <sphere radius="0.001"/>
      </geometry>
    </collision>
  </link>
  <link name="1_4x4_14_base2x">
    <visual>
      <geometry>
        <sphere radius="0.0001"/>
      </geometry>
      <origin rpy="0 0 0" xyz="0.010033199999999999 0.00481666 0.004"/>
      <material name="blue"/>
    </visual>
    <collision>
      <geometry>
        <sphere radius="0.0001"/>
      </geometry>
    </collision>
  </link>
  <link name="1_4x4_14_x2y">
    <visual>
      <geometry>
        <sphere radius="0.0001"/>
      </geometry>
      <origin rpy="0 0 0" xyz="0.0 0.0 0.0"/>
      <material name="blue"/>
    </visual>
    <collision>
      <geometry>
        <sphere radius="0.0001"/>
      </geometry>
    </collision>
  </link>
  <joint name="1_4x4_14_joint_x" type="prismatic">
    <origin rpy="0.0 0.0 0.0" xyz="0.010033199999999999 0.00481666 0.004"/>
    <parent link="1_4x4_base_link"/>
    <child link="1_4x4_14_base2x"/>
    <axis xyz="1 0 0"/>
    <limit effort="100.0" lower="-0.0015" upper="0.0015" velocity="0.5"/>
  </joint>
  <joint name="1_4x4_14_joint_y" type="prismatic">
    <origin rpy="0.0 0.0 0.0" xyz="0.0 0.0 0.0"/>
    <parent link="1_4x4_14_base2x"/>
    <child link="1_4x4_14_x2y"/>
    <axis xyz="0 1 0"/>
    <limit effort="100.0" lower="-0.0015" upper="0.0015" velocity="0.5"/>
  </joint>
  <joint name="1_4x4_14_joint_z" type="prismatic">
    <origin rpy="0.0 0.0 0.0" xyz="0.0 0.0 0.0"/>
    <parent link="1_4x4_14_x2y"/>
    <child link="1_4x4_14_taxel_base_link"/>
    <axis xyz="0 0 1"/>
    <limit effort="100.0" lower="-0.001" upper="0.000" velocity="0.5"/>
  </joint>
  <link name="1_4x4_15_taxel_base_link">
    <visual>
      <geometry>
        <sphere radius="0.001"/>
      </geometry>
      <origin rpy="0 0 0" xyz="0.0 0.0 0.0"/>
      <material name="blue"/>
    </visual>
    <collision>
      <geometry>
        <sphere radius="0.001"/>
      </geometry>
    </collision>
  </link>
  <link name="1_4x4_15_base2x">
    <visual>
      <geometry>
        <sphere radius="0.0001"/>
      </geometry>
      <origin rpy="0 0 0" xyz="0.014699799999999999 0.00481666 0.004"/>
      <material name="blue"/>
    </visual>
    <collision>
      <geometry>
        <sphere radius="0.0001"/>
      </geometry>
    </collision>
  </link>
  <link name="1_4x4_15_x2y">
    <visual>
      <geometry>
        <sphere radius="0.0001"/>
      </geometry>
      <origin rpy="0 0 0" xyz="0.0 0.0 0.0"/>
      <material name="blue"/>
    </visual>
    <collision>
      <geometry>
        <sphere radius="0.0001"/>
      </geometry>
    </collision>
  </link>
  <joint name="1_4x4_15_joint_x" type="prismatic">
    <origin rpy="0.0 0.0 0.0" xyz="0.014699799999999999 0.00481666 0.004"/>
    <parent link="1_4x4_base_link"/>
    <child link="1_4x4_15_base2x"/>
    <axis xyz="1 0 0"/>
    <limit effort="100.0" lower="-0.0015" upper="0.0015" velocity="0.5"/>
  </joint>
  <joint name="1_4x4_15_joint_y" type="prismatic">
    <origin rpy="0.0 0.0 0.0" xyz="0.0 0.0 0.0"/>
    <parent link="1_4x4_15_base2x"/>
    <child link="1_4x4_15_x2y"/>
    <axis xyz="0 1 0"/>
    <limit effort="100.0" lower="-0.0015" upper="0.0015" velocity="0.5"/>
  </joint>
  <joint name="1_4x4_15_joint_z" type="prismatic">
    <origin rpy="0.0 0.0 0.0" xyz="0.0 0.0 0.0"/>
    <parent link="1_4x4_15_x2y"/>
    <child link="1_4x4_15_taxel_base_link"/>
    <axis xyz="0 0 1"/>
    <limit effort="100.0" lower="-0.001" upper="0.000" velocity="0.5"/>
  </joint>
  <link name="1_4x4_16_taxel_base_link">
    <visual>
      <geometry>
        <sphere radius="0.001"/>
      </geometry>
      <origin rpy="0 0 0" xyz="0.0 0.0 0.0"/>
      <material name="blue"/>
    </visual>
    <collision>
      <geometry>
        <sphere radius="0.001"/>
      </geometry>
    </collision>
  </link>
  <link name="1_4x4_16_base2x">
    <visual>
      <geometry>
        <sphere radius="0.0001"/>
      </geometry>
      <origin rpy="0 0 0" xyz="0.0193664 0.00481666 0.004"/>
      <material name="blue"/>
    </visual>
    <collision>
      <geometry>
        <sphere radius="0.0001"/>
      </geometry>
    </collision>
  </link>
  <link name="1_4x4_16_x2y">
    <visual>
      <geometry>
        <sphere radius="0.0001"/>
      </geometry>
      <origin rpy="0 0 0" xyz="0.0 0.0 0.0"/>
      <material name="blue"/>
    </visual>
    <collision>
      <geometry>
        <sphere radius="0.0001"/>
      </geometry>
    </collision>
  </link>
  <joint name="1_4x4_16_joint_x" type="prismatic">
    <origin rpy="0.0 0.0 0.0" xyz="0.0193664 0.00481666 0.004"/>
    <parent link="1_4x4_base_link"/>
    <child link="1_4x4_16_base2x"/>
    <axis xyz="1 0 0"/>
    <limit effort="100.0" lower="-0.0015" upper="0.0015" velocity="0.5"/>
  </joint>
  <joint name="1_4x4_16_joint_y" type="prismatic">
    <origin rpy="0.0 0.0 0.0" xyz="0.0 0.0 0.0"/>
    <parent link="1_4x4_16_base2x"/>
    <child link="1_4x4_16_x2y"/>
    <axis xyz="0 1 0"/>
    <limit effort="100.0" lower="-0.0015" upper="0.0015" velocity="0.5"/>
  </joint>
  <joint name="1_4x4_16_joint_z" type="prismatic">
    <origin rpy="0.0 0.0 0.0" xyz="0.0 0.0 0.0"/>
    <parent link="1_4x4_16_x2y"/>
    <child link="1_4x4_16_taxel_base_link"/>
    <axis xyz="0 0 1"/>
    <limit effort="100.0" lower="-0.001" upper="0.000" velocity="0.5"/>
  </joint>
</robot>

