<?xml version="1.0" ?>
<!-- =================================================================================== -->
<!-- |    This document was autogenerated by xacro from allegro_hand_right.xacro       | -->
<!-- |    EDITING THIS FILE BY HAND IS NOT RECOMMENDED                                 | -->
<!-- =================================================================================== -->
<robot name="allegro_hand_right">
  <!-- Rviz colors -->
  <material name="black">
    <color rgba="0.0 0.0 0.0 1.0"/>
  </material>
  <material name="blue">
    <color rgba="0.0 0.0 0.8 1.0"/>
  </material>
  <material name="green">
    <color rgba="0.0 0.8 0.0 1.0"/>
  </material>
  <material name="grey">
    <color rgba="0.2 0.2 0.2 1.0"/>
  </material>
  <material name="orange">
    <color rgba="1.0 0.4235294117647059 0.0392156862745098 1.0"/>
  </material>
  <material name="brown">
    <color rgba="0.8705882352941177 0.8117647058823529 0.7647058823529411 1.0"/>
  </material>
  <material name="red">
    <color rgba="0.8 0.0 0.0 1.0"/>
  </material>
  <material name="white">
    <color rgba="1.0 1.0 1.0 1.0"/>
  </material>
  <link name="world"/>
  <joint name="fixed" type="fixed">
    <parent link="world"/>
    <child link="base_link"/>
  </joint>
  <link name="base_link">
    <visual>
      <geometry>
        <sphere radius="0.001"/>
      </geometry>
      <origin rpy="0 0 0" xyz="0.0 0.0 0.0"/>
    </visual>
    <collision>
      <geometry>
        <sphere radius="0.001"/>
      </geometry>
    </collision>
  </link>
  <link name="1_ahr_base_link">
    <visual>
      <geometry>
        <mesh filename="package://xela_models/mesh/allegro/base.stl"/>
      </geometry>
      <origin rpy="0 0 0" xyz="0 0 0 "/>
      <material name="cyan">
        <color rgba="0.0 1.0 1.0 1"/>
      </material>
    </visual>
    <collision>
      <origin rpy="0 0 0" xyz="-0.009300 0 -0.0475"/>
      <geometry>
        <box size="0.0408 0.1130 0.095"/>
      </geometry>
    </collision>
  </link>
  <joint name="1_ahr_fixed" type="fixed">
    <origin rpy="0.0 0.0 0.0" xyz="0.0 0.0 0.0"/>
    <parent link="base_link"/>
    <child link="1_ahr_base_link"/>
  </joint>
  <joint name="1_ahr_palm_1_4x6_fixed" type="fixed">
    <origin rpy="1.5707963267948966 0.0 1.5707963267948966" xyz="0.013 -0.051 -0.0365"/>
    <parent link="1_ahr_base_link"/>
    <child link="1_ahr_palm_1_4x6_base_link"/>
  </joint>
  <link name="1_ahr_palm_1_4x6_base_link">
    <collision>
      <origin rpy="0 0 0" xyz="0 0 0"/>
      <geometry>
        <mesh filename="package://xela_models/mesh/4x6.stl"/>
      </geometry>
    </collision>
    <visual>
      <origin rpy="0 0 0" xyz="0 0 0"/>
      <geometry>
        <mesh filename="package://xela_models/mesh/4x6.stl"/>
      </geometry>
      <material name="red"/>
    </visual>
  </link>
  <joint name="1_ahr_palm_2_4x6_fixed" type="fixed">
    <origin rpy="1.5707963267948966 3.141592653589793 1.5707963267948966" xyz="0.013 0.0523 -0.005"/>
    <parent link="1_ahr_base_link"/>
    <child link="1_ahr_palm_2_4x6_base_link"/>
  </joint>
  <link name="1_ahr_palm_2_4x6_base_link">
    <collision>
      <origin rpy="0 0 0" xyz="0 0 0"/>
      <geometry>
        <mesh filename="package://xela_models/mesh/4x6.stl"/>
      </geometry>
    </collision>
    <visual>
      <origin rpy="0 0 0" xyz="0 0 0"/>
      <geometry>
        <mesh filename="package://xela_models/mesh/4x6.stl"/>
      </geometry>
      <material name="green"/>
    </visual>
  </link>
  <joint name="1_ahr_palm_3_4x6_fixed" type="fixed">
    <origin rpy="1.5707963267948966 0.0 1.5707963267948966" xyz="0.013 -0.051 -0.068"/>
    <parent link="1_ahr_base_link"/>
    <child link="1_ahr_palm_3_4x6_base_link"/>
  </joint>
  <link name="1_ahr_palm_3_4x6_base_link">
    <collision>
      <origin rpy="0 0 0" xyz="0 0 0"/>
      <geometry>
        <mesh filename="package://xela_models/mesh/4x6.stl"/>
      </geometry>
    </collision>
    <visual>
      <origin rpy="0 0 0" xyz="0 0 0"/>
      <geometry>
        <mesh filename="package://xela_models/mesh/4x6.stl"/>
      </geometry>
      <material name="blue"/>
    </visual>
  </link>
  <link name="1_hitosashi_finger_finger_link_0">
    <visual>
      <geometry>
        <mesh filename="package://xela_models/mesh/allegro/link_0.0_ext.STL"/>
      </geometry>
      <material name="grey"/>
    </visual>
    <collision>
      <geometry>
        <box size="0.0196 0.0275 0.0164"/>
      </geometry>
      <origin rpy="0 0 0" xyz="0 0 0.011200000000000002"/>
    </collision>
  </link>
  <joint name="1_hitosashi_finger_finger_joint_0" type="revolute">
    <axis xyz="0 0 1"/>
    <limit effort="0" lower="-0.47" upper="0.47" velocity="0"/>
    <parent link="1_ahr_base_link"/>
    <child link="1_hitosashi_finger_finger_link_0"/>
    <origin rpy="-0.08726646259971647 0 0" xyz="0 0.0435 -0.001542"/>
  </joint>
  <link name="1_hitosashi_finger_finger_link_1">
    <visual>
      <geometry>
        <mesh filename="package://xela_models/mesh/allegro/link_1.1.stl"/>
      </geometry>
      <material name="black"/>
    </visual>
    <collision>
      <geometry>
        <box size="0.0196 0.0275 0.054"/>
      </geometry>
      <origin rpy="0 0 0" xyz="0 0 0.027"/>
    </collision>
  </link>
  <link name="1_hitosashi_finger_finger_link_1_cover">
    <visual>
      <geometry>
        <mesh filename="package://xela_models/mesh/allegro/link_1_cover.stl"/>
      </geometry>
      <material name="red"/>
    </visual>
    <collision>
      <geometry>
        <mesh filename="package://xela_models/mesh/allegro/link_1_cover.stl"/>
      </geometry>
      <origin rpy="0 0 0" xyz="0 0 0.00885"/>
    </collision>
  </link>
  <joint name="1_hitosashi_finger_finger_link_1_cover_joint" type="fixed">
    <origin rpy="0.0 0.0 0.0" xyz="0.0 0.0 0.0"/>
    <parent link="1_hitosashi_finger_finger_link_1"/>
    <child link="1_hitosashi_finger_finger_link_1_cover"/>
  </joint>
  <joint name="1_hitosashi_finger_finger_link_1A_4x4_fixed" type="fixed">
    <origin rpy="0.0 -1.5707963267948966 3.141592653589793" xyz="0.0108 0.012 0.033"/>
    <parent link="1_hitosashi_finger_finger_link_1"/>
    <child link="1_hitosashi_finger_finger_link_1A_4x4_base_link"/>
  </joint>
  <link name="1_hitosashi_finger_finger_link_1A_4x4_base_link">
    <collision>
      <origin rpy="0 0 0" xyz="0 0 0"/>
      <geometry>
        <mesh filename="package://xela_models/mesh/4x4.stl"/>
      </geometry>
    </collision>
  </link>
  <joint name="1_hitosashi_finger_finger_link_1B_4x4_fixed" type="fixed">
    <origin rpy="0.0 1.5707963267948966 0.0" xyz="0.0108 -0.012 0.021"/>
    <parent link="1_hitosashi_finger_finger_link_1"/>
    <child link="1_hitosashi_finger_finger_link_1B_4x4_base_link"/>
  </joint>
  <link name="1_hitosashi_finger_finger_link_1B_4x4_base_link">
    <collision>
      <origin rpy="0 0 0" xyz="0 0 0"/>
      <geometry>
        <mesh filename="package://xela_models/mesh/4x4.stl"/>
      </geometry>
    </collision>
  </link>
  <joint name="1_hitosashi_finger_finger_joint_1" type="revolute">
    <limit effort="0" lower="-0.19599999999999998" upper="1.6099999999999999" velocity="0"/>
    <axis xyz="0 1 0"/>
    <parent link="1_hitosashi_finger_finger_link_0"/>
    <child link="1_hitosashi_finger_finger_link_1"/>
    <origin xyz="0 0 0.0204"/>
    <!-- New height on fingers -->
  </joint>
  <link name="1_hitosashi_finger_finger_link_2">
    <visual>
      <geometry>
        <mesh filename="package://xela_models/mesh/allegro/link_2.1.stl"/>
      </geometry>
      <material name="black"/>
    </visual>
    <collision>
      <geometry>
        <box size="0.0196 0.0275 0.0384"/>
      </geometry>
      <origin rpy="0 0 0" xyz="0 0 0.0192"/>
    </collision>
  </link>
  <link name="1_hitosashi_finger_finger_link_2_cover">
    <visual>
      <geometry>
        <mesh filename="package://xela_models/mesh/allegro/link_2_cover.stl"/>
      </geometry>
      <material name="red"/>
    </visual>
    <collision>
      <geometry>
        <mesh filename="package://xela_models/mesh/allegro/link_2_cover.stl"/>
      </geometry>
      <origin rpy="0 0 0" xyz="0 0 0.0257"/>
    </collision>
  </link>
  <joint name="1_hitosashi_finger_finger_link_2_cover_joint" type="fixed">
    <origin rpy="0.0 0.0 0.0" xyz="0.0 0.0 0.0"/>
    <parent link="1_hitosashi_finger_finger_link_2"/>
    <child link="1_hitosashi_finger_finger_link_2_cover"/>
  </joint>
  <joint name="1_hitosashi_finger_finger_link_2_4x4_fixed" type="fixed">
    <origin rpy="0.0 1.5707963267948966 0.0" xyz="0.01 -0.012 0.0445"/>
    <parent link="1_hitosashi_finger_finger_link_2"/>
    <child link="1_hitosashi_finger_finger_link_2_4x4_base_link"/>
  </joint>
  <link name="1_hitosashi_finger_finger_link_2_4x4_base_link">
    <collision>
      <origin rpy="0 0 0" xyz="0 0 0"/>
      <geometry>
        <mesh filename="package://xela_models/mesh/4x4.stl"/>
      </geometry>
    </collision>
  </link>
  <joint name="1_hitosashi_finger_finger_joint_2" type="revolute">
    <axis xyz="0 1 0"/>
    <limit effort="0" lower="-0.17400000000000002" upper="1.7089999999999999" velocity="0"/>
    <parent link="1_hitosashi_finger_finger_link_1"/>
    <child link="1_hitosashi_finger_finger_link_2"/>
    <origin xyz="0 0 0.054"/>
  </joint>
  <link name="1_hitosashi_finger_finger_link_3">
    <visual>
      <geometry>
        <mesh filename="package://xela_models/mesh/allegro/link_3.0.STL"/>
      </geometry>
      <material name="black"/>
    </visual>
    <collision>
      <geometry>
        <box size="0.0196 0.0275 0.026699999999999998"/>
      </geometry>
      <origin rpy="0 0 0" xyz="0 0 0.013349999999999999"/>
    </collision>
  </link>
  <joint name="1_hitosashi_finger_finger_joint_3" type="revolute">
    <axis xyz="0 1 0"/>
    <limit effort="0" lower="-0.227" upper="1.6179999999999999" velocity="0"/>
    <parent link="1_hitosashi_finger_finger_link_2"/>
    <child link="1_hitosashi_finger_finger_link_3"/>
    <origin xyz="0 0.0002 0.043"/>
  </joint>
  <joint name="1_hitosashi_finger_finger_0_aftc_fixed" type="fixed">
    <origin rpy="1.5707963267948966 0.0 1.5707963267948966" xyz="-0.013 0.0 0.016"/>
    <parent link="1_hitosashi_finger_finger_link_3"/>
    <child link="1_hitosashi_finger_finger_0_aftc_base_link"/>
  </joint>
  <link name="1_hitosashi_finger_finger_0_aftc_base_link">
    <collision>
      <origin rpy="0 0 0" xyz="0 0 0"/>
      <geometry>
        <mesh filename="package://xela_models/mesh/ft_c_collision.stl"/>
      </geometry>
    </collision>
    <visual>
      <origin rpy="0 0 0" xyz="0 0 0"/>
      <geometry>
        <mesh filename="package://xela_models/mesh/ft_c_visual.stl"/>
      </geometry>
      <material name="red"/>
    </visual>
  </link>
  <link name="1_naka_finger_finger_link_4">
    <visual>
      <geometry>
        <mesh filename="package://xela_models/mesh/allegro/link_0.0_ext.STL"/>
      </geometry>
      <material name="grey"/>
    </visual>
    <collision>
      <geometry>
        <box size="0.0196 0.0275 0.0164"/>
      </geometry>
      <origin rpy="0 0 0" xyz="0 0 0.011200000000000002"/>
    </collision>
  </link>
  <joint name="1_naka_finger_finger_joint_4" type="revolute">
    <axis xyz="0 0 1"/>
    <limit effort="0" lower="-0.47" upper="0.47" velocity="0"/>
    <parent link="1_ahr_base_link"/>
    <child link="1_naka_finger_finger_link_4"/>
    <origin rpy="0.0 0 0" xyz="0 0 0.0007"/>
  </joint>
  <link name="1_naka_finger_finger_link_5">
    <visual>
      <geometry>
        <mesh filename="package://xela_models/mesh/allegro/link_1.1.stl"/>
      </geometry>
      <material name="black"/>
    </visual>
    <collision>
      <geometry>
        <box size="0.0196 0.0275 0.054"/>
      </geometry>
      <origin rpy="0 0 0" xyz="0 0 0.027"/>
    </collision>
  </link>
  <link name="1_naka_finger_finger_link_5_cover">
    <visual>
      <geometry>
        <mesh filename="package://xela_models/mesh/allegro/link_1_cover.stl"/>
      </geometry>
      <material name="red"/>
    </visual>
    <collision>
      <geometry>
        <mesh filename="package://xela_models/mesh/allegro/link_1_cover.stl"/>
      </geometry>
      <origin rpy="0 0 0" xyz="0 0 0.00885"/>
    </collision>
  </link>
  <joint name="1_naka_finger_finger_link_5_cover_joint" type="fixed">
    <origin rpy="0.0 0.0 0.0" xyz="0.0 0.0 0.0"/>
    <parent link="1_naka_finger_finger_link_5"/>
    <child link="1_naka_finger_finger_link_5_cover"/>
  </joint>
  <joint name="1_naka_finger_finger_link_5A_4x4_fixed" type="fixed">
    <origin rpy="0.0 -1.5707963267948966 3.141592653589793" xyz="0.0108 0.012 0.033"/>
    <parent link="1_naka_finger_finger_link_5"/>
    <child link="1_naka_finger_finger_link_5A_4x4_base_link"/>
  </joint>
  <link name="1_naka_finger_finger_link_5A_4x4_base_link">
    <collision>
      <origin rpy="0 0 0" xyz="0 0 0"/>
      <geometry>
        <mesh filename="package://xela_models/mesh/4x4.stl"/>
      </geometry>
    </collision>
  </link>
  <joint name="1_naka_finger_finger_link_5B_4x4_fixed" type="fixed">
    <origin rpy="0.0 1.5707963267948966 0.0" xyz="0.0108 -0.012 0.021"/>
    <parent link="1_naka_finger_finger_link_5"/>
    <child link="1_naka_finger_finger_link_5B_4x4_base_link"/>
  </joint>
  <link name="1_naka_finger_finger_link_5B_4x4_base_link">
    <collision>
      <origin rpy="0 0 0" xyz="0 0 0"/>
      <geometry>
        <mesh filename="package://xela_models/mesh/4x4.stl"/>
      </geometry>
    </collision>
  </link>
  <joint name="1_naka_finger_finger_joint_5" type="revolute">
    <limit effort="0" lower="-0.19599999999999998" upper="1.6099999999999999" velocity="0"/>
    <axis xyz="0 1 0"/>
    <parent link="1_naka_finger_finger_link_4"/>
    <child link="1_naka_finger_finger_link_5"/>
    <origin xyz="0 0 0.0204"/>
    <!-- New height on fingers -->
  </joint>
  <link name="1_naka_finger_finger_link_6">
    <visual>
      <geometry>
        <mesh filename="package://xela_models/mesh/allegro/link_2.1.stl"/>
      </geometry>
      <material name="black"/>
    </visual>
    <collision>
      <geometry>
        <box size="0.0196 0.0275 0.0384"/>
      </geometry>
      <origin rpy="0 0 0" xyz="0 0 0.0192"/>
    </collision>
  </link>
  <link name="1_naka_finger_finger_link_6_cover">
    <visual>
      <geometry>
        <mesh filename="package://xela_models/mesh/allegro/link_2_cover.stl"/>
      </geometry>
      <material name="red"/>
    </visual>
    <collision>
      <geometry>
        <mesh filename="package://xela_models/mesh/allegro/link_2_cover.stl"/>
      </geometry>
      <origin rpy="0 0 0" xyz="0 0 0.0257"/>
    </collision>
  </link>
  <joint name="1_naka_finger_finger_link_6_cover_joint" type="fixed">
    <origin rpy="0.0 0.0 0.0" xyz="0.0 0.0 0.0"/>
    <parent link="1_naka_finger_finger_link_6"/>
    <child link="1_naka_finger_finger_link_6_cover"/>
  </joint>
  <joint name="1_naka_finger_finger_link_6_4x4_fixed" type="fixed">
    <origin rpy="0.0 1.5707963267948966 0.0" xyz="0.01 -0.012 0.0445"/>
    <parent link="1_naka_finger_finger_link_6"/>
    <child link="1_naka_finger_finger_link_6_4x4_base_link"/>
  </joint>
  <link name="1_naka_finger_finger_link_6_4x4_base_link">
    <collision>
      <origin rpy="0 0 0" xyz="0 0 0"/>
      <geometry>
        <mesh filename="package://xela_models/mesh/4x4.stl"/>
      </geometry>
    </collision>
  </link>
  <joint name="1_naka_finger_finger_joint_6" type="revolute">
    <axis xyz="0 1 0"/>
    <limit effort="0" lower="-0.17400000000000002" upper="1.7089999999999999" velocity="0"/>
    <parent link="1_naka_finger_finger_link_5"/>
    <child link="1_naka_finger_finger_link_6"/>
    <origin xyz="0 0 0.054"/>
  </joint>
  <link name="1_naka_finger_finger_link_7">
    <visual>
      <geometry>
        <mesh filename="package://xela_models/mesh/allegro/link_3.0.STL"/>
      </geometry>
      <material name="black"/>
    </visual>
    <collision>
      <geometry>
        <box size="0.0196 0.0275 0.026699999999999998"/>
      </geometry>
      <origin rpy="0 0 0" xyz="0 0 0.013349999999999999"/>
    </collision>
  </link>
  <joint name="1_naka_finger_finger_joint_7" type="revolute">
    <axis xyz="0 1 0"/>
    <limit effort="0" lower="-0.227" upper="1.6179999999999999" velocity="0"/>
    <parent link="1_naka_finger_finger_link_6"/>
    <child link="1_naka_finger_finger_link_7"/>
    <origin xyz="0 0.0002 0.043"/>
  </joint>
  <joint name="1_naka_finger_finger_1_aftc_fixed" type="fixed">
    <origin rpy="1.5707963267948966 0.0 1.5707963267948966" xyz="-0.013 0.0 0.016"/>
    <parent link="1_naka_finger_finger_link_7"/>
    <child link="1_naka_finger_finger_1_aftc_base_link"/>
  </joint>
  <link name="1_naka_finger_finger_1_aftc_base_link">
    <collision>
      <origin rpy="0 0 0" xyz="0 0 0"/>
      <geometry>
        <mesh filename="package://xela_models/mesh/ft_c_collision.stl"/>
      </geometry>
    </collision>
    <visual>
      <origin rpy="0 0 0" xyz="0 0 0"/>
      <geometry>
        <mesh filename="package://xela_models/mesh/ft_c_visual.stl"/>
      </geometry>
      <material name="red"/>
    </visual>
  </link>
  <link name="1_kusuri_finger_finger_link_8">
    <visual>
      <geometry>
        <mesh filename="package://xela_models/mesh/allegro/link_0.0_ext.STL"/>
      </geometry>
      <material name="grey"/>
    </visual>
    <collision>
      <geometry>
        <box size="0.0196 0.0275 0.0164"/>
      </geometry>
      <origin rpy="0 0 0" xyz="0 0 0.011200000000000002"/>
    </collision>
  </link>
  <joint name="1_kusuri_finger_finger_joint_8" type="revolute">
    <axis xyz="0 0 1"/>
    <limit effort="0" lower="-0.47" upper="0.47" velocity="0"/>
    <parent link="1_ahr_base_link"/>
    <child link="1_kusuri_finger_finger_link_8"/>
    <origin rpy="0.08726646259971647 0 0" xyz="0 -0.0435 -0.001542"/>
  </joint>
  <link name="1_kusuri_finger_finger_link_9">
    <visual>
      <geometry>
        <mesh filename="package://xela_models/mesh/allegro/link_1.1.stl"/>
      </geometry>
      <material name="black"/>
    </visual>
    <collision>
      <geometry>
        <box size="0.0196 0.0275 0.054"/>
      </geometry>
      <origin rpy="0 0 0" xyz="0 0 0.027"/>
    </collision>
  </link>
  <link name="1_kusuri_finger_finger_link_9_cover">
    <visual>
      <geometry>
        <mesh filename="package://xela_models/mesh/allegro/link_1_cover.stl"/>
      </geometry>
      <material name="red"/>
    </visual>
    <collision>
      <geometry>
        <mesh filename="package://xela_models/mesh/allegro/link_1_cover.stl"/>
      </geometry>
      <origin rpy="0 0 0" xyz="0 0 0.00885"/>
    </collision>
  </link>
  <joint name="1_kusuri_finger_finger_link_9_cover_joint" type="fixed">
    <origin rpy="0.0 0.0 0.0" xyz="0.0 0.0 0.0"/>
    <parent link="1_kusuri_finger_finger_link_9"/>
    <child link="1_kusuri_finger_finger_link_9_cover"/>
  </joint>
  <joint name="1_kusuri_finger_finger_link_9A_4x4_fixed" type="fixed">
    <origin rpy="0.0 -1.5707963267948966 3.141592653589793" xyz="0.0108 0.012 0.033"/>
    <parent link="1_kusuri_finger_finger_link_9"/>
    <child link="1_kusuri_finger_finger_link_9A_4x4_base_link"/>
  </joint>
  <link name="1_kusuri_finger_finger_link_9A_4x4_base_link">
    <collision>
      <origin rpy="0 0 0" xyz="0 0 0"/>
      <geometry>
        <mesh filename="package://xela_models/mesh/4x4.stl"/>
      </geometry>
    </collision>
  </link>
  <joint name="1_kusuri_finger_finger_link_9B_4x4_fixed" type="fixed">
    <origin rpy="0.0 1.5707963267948966 0.0" xyz="0.0108 -0.012 0.021"/>
    <parent link="1_kusuri_finger_finger_link_9"/>
    <child link="1_kusuri_finger_finger_link_9B_4x4_base_link"/>
  </joint>
  <link name="1_kusuri_finger_finger_link_9B_4x4_base_link">
    <collision>
      <origin rpy="0 0 0" xyz="0 0 0"/>
      <geometry>
        <mesh filename="package://xela_models/mesh/4x4.stl"/>
      </geometry>
    </collision>
  </link>
  <joint name="1_kusuri_finger_finger_joint_9" type="revolute">
    <limit effort="0" lower="-0.19599999999999998" upper="1.6099999999999999" velocity="0"/>
    <axis xyz="0 1 0"/>
    <parent link="1_kusuri_finger_finger_link_8"/>
    <child link="1_kusuri_finger_finger_link_9"/>
    <origin xyz="0 0 0.0204"/>
    <!-- New height on fingers -->
  </joint>
  <link name="1_kusuri_finger_finger_link_10">
    <visual>
      <geometry>
        <mesh filename="package://xela_models/mesh/allegro/link_2.1.stl"/>
      </geometry>
      <material name="black"/>
    </visual>
    <collision>
      <geometry>
        <box size="0.0196 0.0275 0.0384"/>
      </geometry>
      <origin rpy="0 0 0" xyz="0 0 0.0192"/>
    </collision>
  </link>
  <link name="1_kusuri_finger_finger_link_10_cover">
    <visual>
      <geometry>
        <mesh filename="package://xela_models/mesh/allegro/link_2_cover.stl"/>
      </geometry>
      <material name="red"/>
    </visual>
    <collision>
      <geometry>
        <mesh filename="package://xela_models/mesh/allegro/link_2_cover.stl"/>
      </geometry>
      <origin rpy="0 0 0" xyz="0 0 0.0257"/>
    </collision>
  </link>
  <joint name="1_kusuri_finger_finger_link_10_cover_joint" type="fixed">
    <origin rpy="0.0 0.0 0.0" xyz="0.0 0.0 0.0"/>
    <parent link="1_kusuri_finger_finger_link_10"/>
    <child link="1_kusuri_finger_finger_link_10_cover"/>
  </joint>
  <joint name="1_kusuri_finger_finger_link_10_4x4_fixed" type="fixed">
    <origin rpy="0.0 1.5707963267948966 0.0" xyz="0.01 -0.012 0.0445"/>
    <parent link="1_kusuri_finger_finger_link_10"/>
    <child link="1_kusuri_finger_finger_link_10_4x4_base_link"/>
  </joint>
  <link name="1_kusuri_finger_finger_link_10_4x4_base_link">
    <collision>
      <origin rpy="0 0 0" xyz="0 0 0"/>
      <geometry>
        <mesh filename="package://xela_models/mesh/4x4.stl"/>
      </geometry>
    </collision>
  </link>
  <joint name="1_kusuri_finger_finger_joint_10" type="revolute">
    <axis xyz="0 1 0"/>
    <limit effort="0" lower="-0.17400000000000002" upper="1.7089999999999999" velocity="0"/>
    <parent link="1_kusuri_finger_finger_link_9"/>
    <child link="1_kusuri_finger_finger_link_10"/>
    <origin xyz="0 0 0.054"/>
  </joint>
  <link name="1_kusuri_finger_finger_link_11">
    <visual>
      <geometry>
        <mesh filename="package://xela_models/mesh/allegro/link_3.0.STL"/>
      </geometry>
      <material name="black"/>
    </visual>
    <collision>
      <geometry>
        <box size="0.0196 0.0275 0.026699999999999998"/>
      </geometry>
      <origin rpy="0 0 0" xyz="0 0 0.013349999999999999"/>
    </collision>
  </link>
  <joint name="1_kusuri_finger_finger_joint_11" type="revolute">
    <axis xyz="0 1 0"/>
    <limit effort="0" lower="-0.227" upper="1.6179999999999999" velocity="0"/>
    <parent link="1_kusuri_finger_finger_link_10"/>
    <child link="1_kusuri_finger_finger_link_11"/>
    <origin xyz="0 0.0002 0.043"/>
  </joint>
  <joint name="1_kusuri_finger_finger_2_aftc_fixed" type="fixed">
    <origin rpy="1.5707963267948966 0.0 1.5707963267948966" xyz="-0.013 0.0 0.016"/>
    <parent link="1_kusuri_finger_finger_link_11"/>
    <child link="1_kusuri_finger_finger_2_aftc_base_link"/>
  </joint>
  <link name="1_kusuri_finger_finger_2_aftc_base_link">
    <collision>
      <origin rpy="0 0 0" xyz="0 0 0"/>
      <geometry>
        <mesh filename="package://xela_models/mesh/ft_c_collision.stl"/>
      </geometry>
    </collision>
    <visual>
      <origin rpy="0 0 0" xyz="0 0 0"/>
      <geometry>
        <mesh filename="package://xela_models/mesh/ft_c_visual.stl"/>
      </geometry>
      <material name="red"/>
    </visual>
  </link>
  <link name="1_oya_finger_link_12">
    <visual>
      <geometry>
        <mesh filename="package://xela_models/mesh/allegro/link_12.0_right.STL"/>
      </geometry>
      <material name="black">
        <color rgba=".2 .2 .2 1"/>
      </material>
    </visual>
    <collision>
      <geometry>
        <box size="0.0358 0.034 0.0455"/>
      </geometry>
      <origin rpy="0 0 0" xyz="-0.0179 0.009 0.0145"/>
    </collision>
  </link>
  <joint name="1_oya_finger_joint_12" type="revolute">
    <axis xyz="-1 0 0"/>
    <limit effort="0" lower="0.263" upper="1.396" velocity="0"/>
    <parent link="1_ahr_base_link"/>
    <child link="1_oya_finger_link_12"/>
    <origin rpy="0 -1.6580627893946132 -1.5707963267948966" xyz="-0.0182 0.019333 -0.045987"/>
  </joint>
  <link name="1_oya_finger_link_13">
    <visual>
      <geometry>
        <mesh filename="package://xela_models/mesh/allegro/link_13.0.STL"/>
      </geometry>
      <material name="black">
        <color rgba=".2 .2 .2 1"/>
      </material>
    </visual>
    <collision>
      <geometry>
        <box size="0.0196 0.0275 0.0177"/>
      </geometry>
      <origin rpy="0 0 0" xyz="0 0 0.00885"/>
    </collision>
  </link>
  <link name="1_oya_finger_link_13_cover">
    <visual>
      <geometry>
        <mesh filename="package://xela_models/mesh/allegro/thumb_1_cover.stl"/>
      </geometry>
      <material name="red"/>
    </visual>
    <collision>
      <geometry>
        <mesh filename="package://xela_models/mesh/allegro/thumb_1_cover.stl"/>
      </geometry>
      <origin rpy="0 0 0" xyz="0 0 0"/>
    </collision>
  </link>
  <joint name="1_oya_finger_link_13_cover_joint" type="fixed">
    <origin rpy="0.0 0.0 0.0" xyz="0.0 0.0 0.0"/>
    <parent link="1_oya_finger_link_14"/>
    <child link="1_oya_finger_link_13_cover"/>
  </joint>
  <joint name="1_oya_finger_joint_13" type="revolute">
    <axis xyz="0 0 1"/>
    <limit effort="0" lower="-0.10499999999999998" upper="1.1629999999999998" velocity="0"/>
    <parent link="1_oya_finger_link_12"/>
    <child link="1_oya_finger_link_13"/>
    <origin xyz="-0.027 0.005 0.0399"/>
  </joint>
  <link name="1_oya_finger_link_14">
    <visual>
      <geometry>
        <mesh filename="package://xela_models/mesh/allegro/thumb_1.1.stl"/>
      </geometry>
      <material name="black">
          </material>
    </visual>
    <collision>
      <geometry>
        <box size="0.0196 0.0275 0.0514"/>
      </geometry>
      <origin rpy="0 0 0" xyz="0 0 0.0257"/>
    </collision>
  </link>
  <link name="1_oya_finger_link_14_cover">
    <visual>
      <geometry>
        <mesh filename="package://xela_models/mesh/allegro/thumb_2_cover.stl"/>
      </geometry>
      <material name="red"/>
    </visual>
    <collision>
      <geometry>
        <mesh filename="package://xela_models/mesh/allegro/thumb_2_cover.stl"/>
      </geometry>
      <origin rpy="0 0 0" xyz="0 0 0"/>
    </collision>
  </link>
  <joint name="1_oya_finger_link_14_cover_joint" type="fixed">
    <origin rpy="0.0 0.0 0.0" xyz="0.0 0.0 0.0"/>
    <parent link="1_oya_finger_link_15"/>
    <child link="1_oya_finger_link_14_cover"/>
  </joint>
  <joint name="1_oya_finger_link_14_4x4_fixed" type="fixed">
    <origin rpy="0.0 1.5707963267948966 0.0" xyz="0.011 -0.012 0.023"/>
    <parent link="1_oya_finger_link_14"/>
    <child link="1_oya_finger_link_14_4x4_base_link"/>
  </joint>
  <link name="1_oya_finger_link_14_4x4_base_link">
    <collision>
      <origin rpy="0 0 0" xyz="0 0 0"/>
      <geometry>
        <mesh filename="package://xela_models/mesh/4x4.stl"/>
      </geometry>
    </collision>
  </link>
  <joint name="1_oya_finger_joint_14" type="revolute">
    <axis xyz="0 1 0"/>
    <limit effort="0" lower="-0.18899999999999997" upper="1.644" velocity="0"/>
    <parent link="1_oya_finger_link_13"/>
    <child link="1_oya_finger_link_14"/>
    <origin xyz="0 0 0.0177"/>
  </joint>
  <link name="1_oya_finger_link_15">
    <visual>
      <geometry>
        <mesh filename="package://xela_models/mesh/allegro/thumb_2.1.stl"/>
      </geometry>
      <material name="black">
        </material>
    </visual>
    <collision>
      <geometry>
        <box size="0.0196 0.0275 0.042300000000000004"/>
      </geometry>
      <origin rpy="0 0 0" xyz="0 0 0.021150000000000002"/>
    </collision>
  </link>
  <joint name="1_oya_finger_link_15_4x4_fixed" type="fixed">
    <origin rpy="0.0 1.5707963267948966 0.0" xyz="0.011 -0.012 0.021"/>
    <parent link="1_oya_finger_link_15"/>
    <child link="1_oya_finger_link_15_4x4_base_link"/>
  </joint>
  <link name="1_oya_finger_link_15_4x4_base_link">
    <collision>
      <origin rpy="0 0 0" xyz="0 0 0"/>
      <geometry>
        <mesh filename="package://xela_models/mesh/4x4.stl"/>
      </geometry>
    </collision>
  </link>
  <joint name="1_oya_finger_joint_15" type="revolute">
    <axis xyz="0 1 0"/>
    <limit effort="0" lower="-0.162" upper="1.7189999999999999" velocity="0"/>
    <parent link="1_oya_finger_link_14"/>
    <child link="1_oya_finger_link_15"/>
    <origin xyz="0 0 0.0514"/>
  </joint>
  <joint name="1_oya_finger_3_aftc_fixed" type="fixed">
    <origin rpy="1.5707963267948966 0.0 1.5707963267948966" xyz="-0.013 0.0 0.0315"/>
    <parent link="1_oya_finger_link_15"/>
    <child link="1_oya_finger_3_aftc_base_link"/>
  </joint>
  <link name="1_oya_finger_3_aftc_base_link">
    <collision>
      <origin rpy="0 0 0" xyz="0 0 0"/>
      <geometry>
        <mesh filename="package://xela_models/mesh/ft_c_collision.stl"/>
      </geometry>
    </collision>
    <visual>
      <origin rpy="0 0 0" xyz="0 0 0"/>
      <geometry>
        <mesh filename="package://xela_models/mesh/ft_c_visual.stl"/>
      </geometry>
      <material name="green"/>
    </visual>
  </link>
  <!-- Enable the following 2 if you would like to see different options the same time -->
  <!-- <xacro:allegro_hand_right sequence="2" parent="base_link" x="0.2" tips="curved" /> -->
  <!-- <xacro:allegro_hand_right sequence="3" parent="base_link" x="-0.2" covers="0" palm="0" phalanges="0" tips="default"/> -->
</robot>
